Workbook

Sheet Diagrama ER (corregido)

Sheet Tipos de Dato
A1: Tipos de Datos - Tabla Comparativa
A2: # | B2: Tipo de Dato Genérico | C2: Descripción | D2: En PosgreSQL | E2: En MySQL | F2: En MS SQL Server
D3: Versión: | E3: Versión: | F3: Versión:
A4: 1 | B4: AUTOINCREMENTABLE | C4: Se genera automaticamente | D4: SERIAL | E4: AUTO_INCREMENT | F4: IDENTITY(1,1)
A5: =A4+1 -> 2 | B5: UUID | C5: Identificador unico universal | D5: UUID | E5: CHAR(36) | F5: UNIQUEIDENTIFIER
A6: =A5+1 -> 3 | B6: ENTERO | C6: Numero sin parte decimal | D6: INTEGER | E6: INT | F6: INT
A7: =A6+1 -> 4 | B7: DECIMAL | C7: Numero con parte decimal | D7: DECIMAL(p,s) | E7: DECIMAL(p,s) | F7: DECIMAL(p,s)
A8: =A7+1 -> 5 | B8: LÓGICO | C8: Verdadero o falso | D8: BOOLEAN | E8: BOOLEAN | F8: BIT
A9: =A8+1 -> 6 | B9: TEXTO | C9: Texto largo | D9: TEXT | E9: TEXT | F9: TEXT
A10: =A9+1 -> 7 | B10: CARACTER | C10: Texto corto fijo | D10: CHAR(n) | E10: CHAR(n) | F10: CHAR(n)
A11: =A10+1 -> 8 | B11: FECHA | C11: Fecha | D11: DATE | E11: DATE | F11: DATE
A12: =A11+1 -> 9 | B12: FECHA_HORA | C12: Fecha y hora | D12: TIMESTAMP | E12: DATETIME | F12: DATETIME
A13: =A12+1 -> 10 | B13: HORA | C13: Solo hora | D13: TIME | E13: TIME | F13: TIME
A14: =A13+1 -> 11 | B14: URL | C14: Dirrecion web | D14: VARCHAR(255) | E14: VARCHAR(255) | F14: VARCHAR(255)
A15: =A14+1 -> 12 | B15: ENUM | C15: Lista de valores | D15: CHECK | E15: ENUM | F15: CHECK
A16: =A15+1 -> 13 | B16: TEXTO_CORTO | C16: Texto corto | D16: VARCHAR(n) | E16: VARCHAR(n) | F16: VARCHAR(n)
... A21: =A20+1 -> 18 | B21: AUDIO | C21: Audio | D21: BYTEA | E21: BLOB | F21: VARBYNARY(MAX)

Sheet Invetario de Tablas
A1: Modelo Lógico - Tablas resultantes del Diccionario Genérico (corregido)
A2: INVENTARIO DE TABLAS Este inventario es el mismo para los 3 SGBDs: PostgreSQL, MySQL y MS SQL Server. Todos los diccionarios deben tomar la misma cantidad y los mismos nombres de esta tablas
A3: # | B3: Tabla | C3: Descripción Tabla | D3: Observaciones
A4: 1 | B4: apicultor | C4: Personas que producen productos apícolas.
A5: =A4+1 -> 2 | B5: apiario | C5: Lugar donde el apicultor mantiene su producción.
A6: =A5+1 -> 3 | B6: producto | C6: Productos derivados de la apicultura.
A7: =A6+1 -> 4 | B7: cosecha | C7: Temporada o fecha donde se obtiene la producción.
A8: =A7+1 -> 5 | B8: pedido | C8: Solicitud realizada por un consumidor.
A9: =A8+1 -> 6 | B9: detalle_pedido | C9: Información específica de cada producto solicitado.
A10: =A9+1 -> 7 | B10: sensor | C10: Sensores que registran variables ambientales.
A11: =A10+1 -> 8 | B11: medicion_ambiental | C11: Registro de datos ambientales.
A12: =A11+1 -> 9 | B12: alerta | C12: Notificación generada por el sistema.
A13: =A12+1 -> 10 | B13: entidad_financiera | C13: Organización que puede brindar apoyo económico o financiamiento a proyectos o investigaciones del sector apícola
A14: =A13+1 -> 11 | B14: entidad_reguladora | C14: Entidad encargada de supervisar el cumplimiento de normas y emitir certificaciones relacionadas con la producción apícola
A15: =A14+1 -> 12 | B15: cooperativa | C15: Organizacion que apoya procesos productivos
A16: =A15+1 -> 13 | B16: certificacion | C16: Certificacion reguladora que cumple con normas puestas por la entidad reguladora
... A32: =A31+1 -> 29 | B32: lote_producto | C32: Tabla intermedia formada por la cardinalidad M:N entre lote y producto

Sheet Diccionario Datos - PostgreSQL
A1: PostgreSQL - Tablas en Detalle
A3: ='Invetario de Tablas'!A4 -> 1 | B3: Tabla | C3: ='Invetario de Tablas'!B4 -> apicultor | G3: Descripción Tabla | K3: ='Invetario de Tablas'!C4 -> Personas que producen productos apícolas. | X3: Versión
A4: # | B4: Campo | C4: Descripción Campo | G4: Tipo Dato - PostgreSQL | K4: Tamaño | O4: Nulo | R4: PK | T4: FK | V4: UK | X4: Nota/Comentarios
A5: 1 | B5: id_apicultor | C5: Identificador del apicultor | G5: SERIAL | O5: NO | R5: ✔ | V5: ✔
A6: 2 | B6: nombre | C6: Nombre del apicultor | G6: VARCHAR | K6: 50 | O6: NO
A7: 3 | B7: descripcion | C7: Persona que produce productos apicolas | G7: TEXT | O7: SI
A8: 4 | B8: telefono | C8: telefono de la entidad | G8: VARCHAR | K8: 15 | O8: NO | V8: ✔
A9: 5 | B9: correo | C9: correo de la entidad | G9: VARCHAR | K9: 100 | O9: NO | V9: ✔
A11: ='Invetario de Tablas'!A5 -> 2 | B11: Tabla | C11: ='Invetario de Tablas'!B5 -> apiario | G11: Descripción Tabla | K11: ='Invetario de Tablas'!C5 -> Lugar donde el apicultor mantiene su producción. | X11: Versión
A12: # | B12: Campo | C12: Descripción Campo | G12: Tipo Dato - PostgreSQL | K12: Tamaño | O12: Nulo | R12: PK | T12: FK | V12: UK | X12: Nota/Comentarios
A13: 1 | B13: id_apiario | C13: Identificador del apiario | G13: SERIAL | O13: NO | R13: ✔
A14: 2 | B14: id_apicultor | C14: Apicultor dueño del apiario | G14: INTEGER | O14: NO | T14: ✔
A15: 3 | B15: ubicacion | C15: Lugar del apiario | G15: VARCHAR | K15: 50 | O15: NO
A17: ='Invetario de Tablas'!A6 -> 3 | B17: Tabla | C17: ='Invetario de Tablas'!B6 -> producto | G17: Descripción Tabla | K17: ='Invetario de Tablas'!C6 -> Productos derivados de la apicultura. | X17: Versión
A18: # | B18: Campo | C18: Descripción Campo | G18: Tipo Dato - PostgreSQL | K18: Tamaño | O18: Nulo | R18: PK | T18: FK | V18: UK | X18: Nota/Comentarios
A19: 1 | B19: id_producto | C19: Productos derivados de la apicultura | G19: SERIAL | O19: NO | R19: ✔
A20: 2 | B20: tipo_producto | C20: Tipo de producto apicola | G20: VARCHAR | K20: 50 | O20: NO
A21: 3 | B21: descripcion | C21: Descripcion del producto | G21: TEXT | O21: SI
A23: ='Invetario de Tablas'!A7 -> 4 | B23: Tabla | C23: ='Invetario de Tablas'!B7 -> cosecha | G23: Descripción Tabla | K23: ='Invetario de Tablas'!C7 -> Temporada o fecha donde se obtiene la producción. | X23: Versión
A24: # | B24: Campo | C24: Descripción Campo | G24: Tipo Dato - PostgreSQL | K24: Tamaño | O24: Nulo | R24: PK | T24: FK | V24: UK | X24: Nota/Comentarios
A25: 1 | B25: id_cosecha | C25: Identificador de la cosecha | G25: SERIAL | O25: NO | R25: ✔
A26: 2 | B26: id_apiario | C26: Apiario donde se realiza la cosecha | G26: INTEGER | O26: NO | T26: ✔
A27: 3 | B27: fecha | C27: Fecha de la cosecha | G27: DATE | O27: NO
A29: ='Invetario de Tablas'!A8 -> 5 | B29: Tabla | C29: ='Invetario de Tablas'!B8 -> pedido | G29: Descripción Tabla | K29: ='Invetario de Tablas'!C8 -> Solicitud realizada por un consumidor. | X29: Versión
A30: # | B30: Campo | C30: Descripción Campo | G30: Tipo Dato - PostgreSQL | K30: Tamaño | O30: Nulo | R30: PK | T30: FK | V30: UK | X30: Nota/Comentarios
A31: 1 | B31: id_pedido | C31: Identificador del pedido | G31: SERIAL | O31: NO | R31: ✔ | V31: ✔
A32: 2 | B32: id_consumidor | C32: Consumidor que realiza el pedido | G32: INTEGER | O32: NO | T32: ✔
A33: 3 | B33: fecha | C33: Fecha en la que se realiza el pedido | G33: DATE | O33: NO
A35: ='Invetario de Tablas'!A9 -> 6 | B35: Tabla | C35: ='Invetario de Tablas'!B9 -> detalle_pedido | G35: Descripción Tabla | K35: ='Invetario de Tablas'!C9 -> Información específica de cada producto solicitado. | X35: Versión
A36: # | B36: Campo | C36: Descripción Campo | G36: Tipo Dato - PostgreSQL | K36: Tamaño | O36: Nulo | R36: PK | T36: FK | V36: UK | X36: Nota/Comentarios
A37: 1 | B37: id_pedido | C37: Pedido al que pertenece el producto | G37: INTEGER | O37: NO | R37: ✔ | T37: ✔
A38: 2 | B38: id_lote | C38: Lote del producto solicitado | G38: INTEGER | O38: NO | R38: ✔ | T38: ✔
A39: 3 | B39: cantidad | C39: Cantidad solicitada del producto | G39: INTEGER | O39: NO
A41: ='Invetario de Tablas'!A10 -> 7 | B41: Tabla | C41: ='Invetario de Tablas'!B10 -> sensor | G41: Descripción Tabla | K41: ='Invetario de Tablas'!C10 -> Sensores que registran variables ambientales. | X41: Versión
A42: # | B42: Campo | C42: Descripción Campo | G42: Tipo Dato - PostgreSQL | K42: Tamaño | O42: Nulo | R42: PK | T42: FK | V42: UK | X42: Nota/Comentarios
A43: 1 | B43: id_sensor | C43: Identificador del sensor | G43: SERIAL | O43: NO | R43: ✔ | V43: ✔
A44: 2 | B44: tipo_sensor | C44: Tipo de sensor utilizado | G44: VARCHAR | K44: 50 | O44: NO
A46: ='Invetario de Tablas'!A11 -> 8 | B46: Tabla | C46: ='Invetario de Tablas'!B11 -> medicion_ambiental | G46: Descripción Tabla | K46: ='Invetario de Tablas'!C11 -> Registro de datos ambientales. | X46: Versión
A47: # | B47: Campo | C47: Descripción Campo | G47: Tipo Dato - PostgreSQL | K47: Tamaño | O47: Nulo | R47: PK | T47: FK | V47: UK | X47: Nota/Comentarios
A48: 1 | B48: id_medicion | C48: Identificador de la medición | G48: SERIAL | O48: NO | R48: ✔ | V48: ✔
...

Sheet Diccionario Datos - MySQL
A1: MySQL - Tablas en Detalle
A3: ='Invetario de Tablas'!A4 -> 1 | B3: Tabla | C3: ='Invetario de Tablas'!B4 -> apicultor | G3: Descripción Tabla | K3: ='Invetario de Tablas'!C4 -> Personas que producen productos apícolas. | X3: Versión
A4: # | B4: Campo | C4: Descripción Campo | G4: Tipo Dato - MySQL | K4: Tamaño | O4: Nulo | R4: PK | T4: FK | V4: UK | X4: Nota/Comentarios
A5: 1 | B5: id_apicultor | C5: Identificador del apicultor | G5: INT AUTO_INCREMENT | K5: 11 | O5: NO | R5: ✔ | V5: ✔
A6: 2 | B6: nombre | C6: Nombre del apicultor | G6: VARCHAR | K6: 50 | O6: NO
A7: 3 | B7: descripcion | C7: Persona que produce productos apicolas | G7: TEXT | O7: SI
A8: 4 | B8: telefono | C8: telefono de la entidad | G8: VARCHAR | K8: 15 | O8: NO | V8: ✔
A9: 5 | B9: correo | C9: correo de la entidad | G9: VARCHAR | K9: 100 | O9: NO | V9: ✔
A11: ='Invetario de Tablas'!A5 -> 2 | B11: Tabla | C11: ='Invetario de Tablas'!B5 -> apiario | G11: Descripción Tabla | K11: ='Invetario de Tablas'!C5 -> Lugar donde el apicultor mantiene su producción. | X11: Versión
A12: # | B12: Campo | C12: Descripción Campo | G12: Tipo Dato - MySQL | K12: Tamaño | O12: Nulo | R12: PK | T12: FK | V12: UK | X12: Nota/Comentarios
A13: 1 | B13: id_apiario | C13: Identificador del apiario | G13: INT AUTO_INCREMENT | K13: 11 | O13: NO | R13: ✔
A14: 2 | B14: id_apicultor | C14: Apicultor dueño del apiario | G14: INT | K14: 11 | O14: NO | T14: ✔
A15: 3 | B15: ubicacion | C15: Lugar del apiario | G15: VARCHAR | K15: 50 | O15: NO
A17: ='Invetario de Tablas'!A6 -> 3 | B17: Tabla | C17: ='Invetario de Tablas'!B6 -> producto | G17: Descripción Tabla | K17: ='Invetario de Tablas'!C6 -> Productos derivados de la apicultura. | X17: Versión
A18: # | B18: Campo | C18: Descripción Campo | G18: Tipo Dato - MySQL | K18: Tamaño | O18: Nulo | R18: PK | T18: FK | V18: UK | X18: Nota/Comentarios
A19: 1 | B19: id_producto | C19: Productos derivados de la apicultura | G19: INT AUTO_INCREMENT | K19: 11 | O19: NO | R19: ✔
A20: 2 | B20: tipo_producto | C20: Tipo de producto apicola | G20: VARCHAR | K20: 50 | O20: NO
A21: 3 | B21: descripcion | C21: Descripcion del producto | G21: TEXT | O21: SI
A23: ='Invetario de Tablas'!A7 -> 4 | B23: Tabla | C23: ='Invetario de Tablas'!B7 -> cosecha | G23: Descripción Tabla | K23: ='Invetario de Tablas'!C7 -> Temporada o fecha donde se obtiene la producción. | X23: Versión
A24: # | B24: Campo | C24: Descripción Campo | G24: Tipo Dato - MySQL | K24: Tamaño | O24: Nulo | R24: PK | T24: FK | V24: UK | X24: Nota/Comentarios
A25: 1 | B25: id_cosecha | C25: Identificador de la cosecha | G25: INT AUTO_INCREMENT | K25: 11 | O25: NO | R25: ✔
A26: 2 | B26: id_apiario | C26: Apiario donde se realiza la cosecha | G26: INT | K26: 11 | O26: NO | T26: ✔
A27: 3 | B27: fecha | C27: Fecha de la cosecha | G27: DATE | O27: NO
A29: ='Invetario de Tablas'!A8 -> 5 | B29: Tabla | C29: ='Invetario de Tablas'!B8 -> pedido | G29: Descripción Tabla | K29: ='Invetario de Tablas'!C8 -> Solicitud realizada por un consumidor. | X29: Versión
A30: # | B30: Campo | C30: Descripción Campo | G30: Tipo Dato - MySQL | K30: Tamaño | O30: Nulo | R30: PK | T30: FK | V30: UK | X30: Nota/Comentarios
A31: 1 | B31: id_pedido | C31: Identificador del pedido | G31: INT AUTO_INCREMENT | K31: 11 | O31: NO | R31: ✔ | V31: ✔
A32: 2 | B32: id_consumidor | C32: Consumidor que realiza el pedido | G32: INT | K32: 11 | O32: NO | T32: ✔
A33: 3 | B33: fecha | C33: Fecha en la que se realiza el pedido | G33: DATE | O33: NO
A35: ='Invetario de Tablas'!A9 -> 6 | B35: Tabla | C35: ='Invetario de Tablas'!B9 -> detalle_pedido | G35: Descripción Tabla | K35: ='Invetario de Tablas'!C9 -> Información específica de cada producto solicitado. | X35: Versión
A36: # | B36: Campo | C36: Descripción Campo | G36: Tipo Dato - MySQL | K36: Tamaño | O36: Nulo | R36: PK | T36: FK | V36: UK | X36: Nota/Comentarios
A37: 1 | B37: id_pedido | C37: Pedido al que pertenece el producto | G37: INT | K37: 11 | O37: NO | R37: ✔ | T37: ✔
A38: 2 | B38: id_lote | C38: Lote del producto solicitado | G38: INT | K38: 11 | O38: NO | R38: ✔ | T38: ✔
A39: 3 | B39: cantidad | C39: Cantidad solicitada del producto | G39: INT | K39: 11 | O39: NO
A41: ='Invetario de Tablas'!A10 -> 7 | B41: Tabla | C41: ='Invetario de Tablas'!B10 -> sensor | G41: Descripción Tabla | K41: ='Invetario de Tablas'!C10 -> Sensores que registran variables ambientales. | X41: Versión
A42: # | B42: Campo | C42: Descripción Campo | G42: Tipo Dato - MySQL | K42: Tamaño | O42: Nulo | R42: PK | T42: FK | V42: UK | X42: Nota/Comentarios
A43: 1 | B43: id_sensor | C43: Identificador del sensor | G43: INT AUTO_INCREMENT | K43: 11 | O43: NO | R43: ✔ | V43: ✔
A44: 2 | B44: tipo_sensor | C44: Tipo de sensor utilizado | G44: VARCHAR | K44: 50 | O44: NO
A46: ='Invetario de Tablas'!A11 -> 8 | B46: Tabla | C46: ='Invetario de Tablas'!B11 -> medicion_ambiental | G46: Descripción Tabla | K46: ='Invetario de Tablas'!C11 -> Registro de datos ambientales. | X46: Versión
A47: # | B47: Campo | C47: Descripción Campo | G47: Tipo Dato - MySQL | K47: Tamaño | O47: Nulo | R47: PK | T47: FK | V47: UK | X47: Nota/Comentarios
A48: 1 | B48: id_medicion | C48: Identificador de la medición | G48: INT AUTO_INCREMENT | K48: 11 | O48: NO | R48: ✔ | V48: ✔
...

Sheet Diccionario Datos - MS SQL Serv
A1: MS SQL Server - Tablas en Detalle
A3: ='Invetario de Tablas'!A4 -> 1 | B3: Tabla | C3: ='Invetario de Tablas'!B4 -> apicultor | G3: Descripción Tabla | K3: ='Invetario de Tablas'!C4 -> Personas que producen productos apícolas. | X3: Versión
A4: # | B4: Campo | C4: Descripción Campo | G4: Tipo Dato - MS SQL Server | K4: Tamaño | O4: Nulo | R4: PK | T4: FK | V4: UK | X4: Nota/Comentarios
A5: 1 | B5: id_apicultor | C5: Identificador del apicultor | G5: INT IDENTITY | K5: 1,1 | O5: NO | R5: ✔ | V5: ✔
A6: 2 | B6: nombre | C6: Nombre del apicultor | G6: VARCHAR | K6: 50 | O6: NO
A7: 3 | B7: descripcion | C7: Persona que produce productos apicolas | G7: VARCHAR | K7: MAX | O7: SI
A8: 4 | B8: telefono | C8: telefono de la entidad | G8: VARCHAR | K8: 15 | O8: NO | V8: ✔
A9: 5 | B9: correo | C9: correo de la entidad | G9: VARCHAR | K9: 100 | O9: NO | V9: ✔
A11: ='Invetario de Tablas'!A5 -> 2 | B11: Tabla | C11: ='Invetario de Tablas'!B5 -> apiario | G11: Descripción Tabla | K11: ='Invetario de Tablas'!C5 -> Lugar donde el apicultor mantiene su producción. | X11: Versión
A12: # | B12: Campo | C12: Descripción Campo | G12: Tipo Dato - MS SQL Server | K12: Tamaño | O12: Nulo | R12: PK | T12: FK | V12: UK | X12: Nota/Comentarios
A13: 1 | B13: id_apiario | C13: Identificador del apiario | G13: INT IDENTITY | K13: 1,1 | O13: NO | R13: ✔
A14: 2 | B14: id_apicultor | C14: Apicultor dueño del apiario | G14: INT | O14: NO | T14: ✔
A15: 3 | B15: ubicacion | C15: Lugar del apiario | G15: VARCHAR | K15: 50 | O15: NO
A17: ='Invetario de Tablas'!A6 -> 3 | B17: Tabla | C17: ='Invetario de Tablas'!B6 -> producto | G17: Descripción Tabla | K17: ='Invetario de Tablas'!C6 -> Productos derivados de la apicultura. | X17: Versión
A18: # | B18: Campo | C18: Descripción Campo | G18: Tipo Dato - MS SQL Server | K18: Tamaño | O18: Nulo | R18: PK | T18: FK | V18: UK | X18: Nota/Comentarios
A19: 1 | B19: id_producto | C19: Productos derivados de la apicultura | G19: INT IDENTITY | K19: 1,1 | O19: NO | R19: ✔
A20: 2 | B20: tipo_producto | C20: Tipo de producto apicola | G20: VARCHAR | K20: 50 | O20: NO
A21: 3 | B21: descripcion | C21: Descripcion del producto | G21: VARCHAR | K21: MAX | O21: SI
A23: ='Invetario de Tablas'!A7 -> 4 | B23: Tabla | C23: ='Invetario de Tablas'!B7 -> cosecha | G23: Descripción Tabla | K23: ='Invetario de Tablas'!C7 -> Temporada o fecha donde se obtiene la producción. | X23: Versión
A24: # | B24: Campo | C24: Descripción Campo | G24: Tipo Dato - MS SQL Server | K24: Tamaño | O24: Nulo | R24: PK | T24: FK | V24: UK | X24: Nota/Comentarios
A25: 1 | B25: id_cosecha | C25: Identificador de la cosecha | G25: INT IDENTITY | K25: 1,1 | O25: NO | R25: ✔
A26: 2 | B26: id_apiario | C26: Apiario donde se realiza la cosecha | G26: INT | O26: NO | T26: ✔
A27: 3 | B27: fecha | C27: Fecha de la cosecha | G27: DATE | O27: NO
A29: ='Invetario de Tablas'!A8 -> 5 | B29: Tabla | C29: ='Invetario de Tablas'!B8 -> pedido | G29: Descripción Tabla | K29: ='Invetario de Tablas'!C8 -> Solicitud realizada por un consumidor. | X29: Versión
A30: # | B30: Campo | C30: Descripción Campo | G30: Tipo Dato - MS SQL Server | K30: Tamaño | O30: Nulo | R30: PK | T30: FK | V30: UK | X30: Nota/Comentarios
A31: 1 | B31: id_pedido | C31: Identificador del pedido | G31: INT IDENTITY | K31: 1,1 | O31: NO | R31: ✔ | V31: ✔
A32: 2 | B32: id_consumidor | C32: Consumidor que realiza el pedido | G32: INT | O32: NO | T32: ✔
A33: 3 | B33: fecha | C33: Fecha en la que se realiza el pedido | G33: DATE | O33: NO
A35: ='Invetario de Tablas'!A9 -> 6 | B35: Tabla | C35: ='Invetario de Tablas'!B9 -> detalle_pedido | G35: Descripción Tabla | K35: ='Invetario de Tablas'!C9 -> Información específica de cada producto solicitado. | X35: Versión
A36: # | B36: Campo | C36: Descripción Campo | G36: Tipo Dato - MS SQL Server | K36: Tamaño | O36: Nulo | R36: PK | T36: FK | V36: UK | X36: Nota/Comentarios
A37: 1 | B37: id_pedido | C37: Pedido al que pertenece el producto | G37: INT | O37: NO | R37: ✔ | T37: ✔
A38: 2 | B38: id_lote | C38: Lote del producto solicitado | G38: INT | O38: NO | R38: ✔ | T38: ✔
A39: 3 | B39: cantidad | C39: Cantidad solicitada del producto | G39: INT | O39: NO
A41: ='Invetario de Tablas'!A10 -> 7 | B41: Tabla | C41: ='Invetario de Tablas'!B10 -> sensor | G41: Descripción Tabla | K41: ='Invetario de Tablas'!C10 -> Sensores que registran variables ambientales. | X41: Versión
A42: # | B42: Campo | C42: Descripción Campo | G42: Tipo Dato - MS SQL Server | K42: Tamaño | O42: Nulo | R42: PK | T42: FK | V42: UK | X42: Nota/Comentarios
A43: 1 | B43: id_sensor | C43: Identificador del sensor | G43: INT IDENTITY | K43: 1,1 | O43: NO | R43: ✔ | V43: ✔
A44: 2 | B44: tipo_sensor | C44: Tipo de sensor utilizado | G44: VARCHAR | K44: 50 | O44: NO
A46: ='Invetario de Tablas'!A11 -> 8 | B46: Tabla | C46: ='Invetario de Tablas'!B11 -> medicion_ambiental | G46: Descripción Tabla | K46: ='Invetario de Tablas'!C11 -> Registro de datos ambientales. | X46: Versión
A47: # | B47: Campo | C47: Descripción Campo | G47: Tipo Dato - MS SQL Server | K47: Tamaño | O47: Nulo | R47: PK | T47: FK | V47: UK | X47: Nota/Comentarios
A48: 1 | B48: id_medicion | C48: Identificador de la medición | G48: INT IDENTITY | K48: 1,1 | O48: NO | R48: ✔ | V48: ✔
...
